Workbook

Sheet Dashboard
A2: SAT PERFORMANCE TRACKING DASHBOARD
A3: "The objective is not to get more questions right. The objective is to eliminate recurring error types. Scores improve automatically when recurring errors disappear."
A5: CURRENT SAT SCORE | C5: TARGET SAT SCORE | E5: SCORE GAP | F5: AVG WEEKLY IMPROVEMENT | H5: TESTS COMPLETED | I5: ERRORS LOGGED | J5: CURRENT LARGEST WEAKNESS
A6: =IF(COUNT(F13:F100)=0, "N/A", INDEX(F13:F100, MATCH(9.99E+307, F13:F100))) | C6: 1550 | E6: =IF(ISNUMBER(A6), C6 - A6, "N/A") | F6: =IF(COUNT(F13:F100)<2, 0, (INDEX(F13:F100, MATCH(9.99E+307, F13:F100)) - F13) / MAX(1, (INDEX(A13:A100, MATCH(9.99E+307, F13:F100)) - A13)/7)) | H6: =COUNT(F13:F100) | I6: =COUNTA('Error Log'!A2:A500) | J6: =IF(SUM('Config'!$K$2:$K$39)>0, INDEX('Config'!$J$2:$J$39, MATCH(MAX('Config'!$K$2:$K$39), 'Config'!$K$2:$K$39, 0)), "None")
A12: Date | B12: Practice Test Name | C12: Test Number | D12: Math Score | E12: Reading & Writing Score | F12: Total Score | G12: Math Accuracy % | H12: Reading & Writing Accuracy % | I12: Questions Missed | J12: Time Spent (Min) | K12: Notes | M12: TOPIC MASTERY & STRENGTHS | U12: AUTO-GENERATED STUDY RECOMMENDATIONS (TOP 5)
F13: =IF(AND(ISNUMBER(D13), ISNUMBER(E13)), D13+E13, "") | M13: Topic | N13: Questions Attempted | O13: Questions Correct | P13: Accuracy % | Q13: Errors Logged | R13: Mastery Status | U13: Top Weakest Topics | V13: Accuracy | W13: Top 5 Error Types | X13: Count | Y13: Top 5 Root Causes | Z13: Count
F14: =IF(AND(ISNUMBER(D14), ISNUMBER(E14)), D14+E14, "") | M14: Algebra | P14: =IF(N14>0, O14/N14, 1.0) | Q14: =COUNTIFS('Error Log'!$F$2:$F$500, M14) | R14: =IF(P14>=0.9, "Mastered", IF(P14>=0.8, "Strong", IF(P14>=0.7, "Developing", "Weak"))) | S14: =P14+ROW()/100000 | U14: =IF(INDEX(N$14:N$21, MATCH(SMALL(S$14:S$21, 1), S$14:S$21, 0))>0, INDEX(M$14:M$21, MATCH(SMALL(S$14:S$21, 1), S$14:S$21, 0)), "") | V14: =IF(U14="", "", INDEX(P$14:P$21, MATCH(SMALL(S$14:S$21, 1), S$14:S$21, 0))) | W14: =IF(INDEX('Config'!$K$2:$K$39, MATCH(LARGE('Config'!$L$2:$L$39, 1), 'Config'!$L$2:$L$39, 0))>0, INDEX('Config'!$J$2:$J$39, MATCH(LARGE('Config'!$L$2:$L$39, 1), 'Config'!$L$2:$L$39, 0)), "") | X14: =IF(W14="", "", INDEX('Config'!$K$2:$K$39, MATCH(LARGE('Config'!$L$2:$L$39, 1), 'Config'!$L$2:$L$39, 0))) | Y14: =IF(INDEX('Config'!$O$2:$O$41, MATCH(LARGE('Config'!$P$2:$P$41, 1), 'Config'!$P$2:$P$41, 0))>0, INDEX('Config'!$N$2:$N$41, MATCH(LARGE('Config'!$P$2:$P$41, 1), 'Config'!$P$2:$P$41, 0)), "") | Z14: =IF(Y14="", "", INDEX('Config'!$O$2:$O$41, MATCH(LARGE('Config'!$P$2:$P$41, 1), 'Config'!$P$2:$P$41, 0)))
F15: =IF(AND(ISNUMBER(D15), ISNUMBER(E15)), D15+E15, "") | M15: Advanced Math | P15: =IF(N15>0, O15/N15, 1.0) | Q15: =COUNTIFS('Error Log'!$F$2:$F$500, M15) | R15: =IF(P15>=0.9, "Mastered", IF(P15>=0.8, "Strong", IF(P15>=0.7, "Developing", "Weak"))) | S15: =P15+ROW()/100000 | U15: =IF(INDEX(N$14:N$21, MATCH(SMALL(S$14:S$21, 2), S$14:S$21, 0))>0, INDEX(M$14:M$21, MATCH(SMALL(S$14:S$21, 2), S$14:S$21, 0)), "") | V15: =IF(U15="", "", INDEX(P$14:P$21, MATCH(SMALL(S$14:S$21, 2), S$14:S$21, 0))) | W15: =IF(INDEX('Config'!$K$2:$K$39, MATCH(LARGE('Config'!$L$2:$L$39, 2), 'Config'!$L$2:$L$39, 0))>0, INDEX('Config'!$J$2:$J$39, MATCH(LARGE('Config'!$L$2:$L$39, 2), 'Config'!$L$2:$L$39, 0)), "") | X15: =IF(W15="", "", INDEX('Config'!$K$2:$K$39, MATCH(LARGE('Config'!$L$2:$L$39, 2), 'Config'!$L$2:$L$39, 0))) | Y15: =IF(INDEX('Config'!$O$2:$O$41, MATCH(LARGE('Config'!$P$2:$P$41, 2), 'Config'!$P$2:$P$41, 0))>0, INDEX('Config'!$N$2:$N$41, MATCH(LARGE('Config'!$P$2:$P$41, 2), 'Config'!$P$2:$P$41, 0)), "") | Z15: =IF(Y15="", "", INDEX('Config'!$O$2:$O$41, MATCH(LARGE('Config'!$P$2:$P$41, 2), 'Config'!$P$2:$P$41, 0)))
F16: =IF(AND(ISNUMBER(D16), ISNUMBER(E16)), D16+E16, "") | M16: Problem Solving & Data Analysis | P16: =IF(N16>0, O16/N16, 1.0) | Q16: =COUNTIFS('Error Log'!$F$2:$F$500, M16) | R16: =IF(P16>=0.9, "Mastered", IF(P16>=0.8, "Strong", IF(P16>=0.7, "Developing", "Weak"))) | S16: =P16+ROW()/100000 | U16: =IF(INDEX(N$14:N$21, MATCH(SMALL(S$14:S$21, 3), S$14:S$21, 0))>0, INDEX(M$14:M$21, MATCH(SMALL(S$14:S$21, 3), S$14:S$21, 0)), "") | V16: =IF(U16="", "", INDEX(P$14:P$21, MATCH(SMALL(S$14:S$21, 3), S$14:S$21, 0))) | W16: =IF(INDEX('Config'!$K$2:$K$39, MATCH(LARGE('Config'!$L$2:$L$39, 3), 'Config'!$L$2:$L$39, 0))>0, INDEX('Config'!$J$2:$J$39, MATCH(LARGE('Config'!$L$2:$L$39, 3), 'Config'!$L$2:$L$39, 0)), "") | X16: =IF(W16="", "", INDEX('Config'!$K$2:$K$39, MATCH(LARGE('Config'!$L$2:$L$39, 3), 'Config'!$L$2:$L$39, 0))) | Y16: =IF(INDEX('Config'!$O$2:$O$41, MATCH(LARGE('Config'!$P$2:$P$41, 3), 'Config'!$P$2:$P$41, 0))>0, INDEX('Config'!$N$2:$N$41, MATCH(LARGE('Config'!$P$2:$P$41, 3), 'Config'!$P$2:$P$41, 0)), "") | Z16: =IF(Y16="", "", INDEX('Config'!$O$2:$O$41, MATCH(LARGE('Config'!$P$2:$P$41, 3), 'Config'!$P$2:$P$41, 0)))
F17: =IF(AND(ISNUMBER(D17), ISNUMBER(E17)), D17+E17, "") | M17: Geometry & Trigonometry | P17: =IF(N17>0, O17/N17, 1.0) | Q17: =COUNTIFS('Error Log'!$F$2:$F$500, M17) | R17: =IF(P17>=0.9, "Mastered", IF(P17>=0.8, "Strong", IF(P17>=0.7, "Developing", "Weak"))) | S17: =P17+ROW()/100000 | U17: =IF(INDEX(N$14:N$21, MATCH(SMALL(S$14:S$21, 4), S$14:S$21, 0))>0, INDEX(M$14:M$21, MATCH(SMALL(S$14:S$21, 4), S$14:S$21, 0)), "") | V17: =IF(U17="", "", INDEX(P$14:P$21, MATCH(SMALL(S$14:S$21, 4), S$14:S$21, 0))) | W17: =IF(INDEX('Config'!$K$2:$K$39, MATCH(LARGE('Config'!$L$2:$L$39, 4), 'Config'!$L$2:$L$39, 0))>0, INDEX('Config'!$J$2:$J$39, MATCH(LARGE('Config'!$L$2:$L$39, 4), 'Config'!$L$2:$L$39, 0)), "") | X17: =IF(W17="", "", INDEX('Config'!$K$2:$K$39, MATCH(LARGE('Config'!$L$2:$L$39, 4), 'Config'!$L$2:$L$39, 0))) | Y17: =IF(INDEX('Config'!$O$2:$O$41, MATCH(LARGE('Config'!$P$2:$P$41, 4), 'Config'!$P$2:$P$41, 0))>0, INDEX('Config'!$N$2:$N$41, MATCH(LARGE('Config'!$P$2:$P$41, 4), 'Config'!$P$2:$P$41, 0)), "") | Z17: =IF(Y17="", "", INDEX('Config'!$O$2:$O$41, MATCH(LARGE('Config'!$P$2:$P$41, 4), 'Config'!$P$2:$P$41, 0)))
F18: =IF(AND(ISNUMBER(D18), ISNUMBER(E18)), D18+E18, "") | M18: Information & Ideas | P18: =IF(N18>0, O18/N18, 1.0) | Q18: =COUNTIFS('Error Log'!$F$2:$F$500, M18) | R18: =IF(P18>=0.9, "Mastered", IF(P18>=0.8, "Strong", IF(P18>=0.7, "Developing", "Weak"))) | S18: =P18+ROW()/100000 | U18: =IF(INDEX(N$14:N$21, MATCH(SMALL(S$14:S$21, 5), S$14:S$21, 0))>0, INDEX(M$14:M$21, MATCH(SMALL(S$14:S$21, 5), S$14:S$21, 0)), "") | V18: =IF(U18="", "", INDEX(P$14:P$21, MATCH(SMALL(S$14:S$21, 5), S$14:S$21, 0))) | W18: =IF(INDEX('Config'!$K$2:$K$39, MATCH(LARGE('Config'!$L$2:$L$39, 5), 'Config'!$L$2:$L$39, 0))>0, INDEX('Config'!$J$2:$J$39, MATCH(LARGE('Config'!$L$2:$L$39, 5), 'Config'!$L$2:$L$39, 0)), "") | X18: =IF(W18="", "", INDEX('Config'!$K$2:$K$39, MATCH(LARGE('Config'!$L$2:$L$39, 5), 'Config'!$L$2:$L$39, 0))) | Y18: =IF(INDEX('Config'!$O$2:$O$41, MATCH(LARGE('Config'!$P$2:$P$41, 5), 'Config'!$P$2:$P$41, 0))>0, INDEX('Config'!$N$2:$N$41, MATCH(LARGE('Config'!$P$2:$P$41, 5), 'Config'!$P$2:$P$41, 0)), "") | Z18: =IF(Y18="", "", INDEX('Config'!$O$2:$O$41, MATCH(LARGE('Config'!$P$2:$P$41, 5), 'Config'!$P$2:$P$41, 0)))
F19: =IF(AND(ISNUMBER(D19), ISNUMBER(E19)), D19+E19, "") | M19: Craft & Structure | P19: =IF(N19>0, O19/N19, 1.0) | Q19: =COUNTIFS('Error Log'!$F$2:$F$500, M19) | R19: =IF(P19>=0.9, "Mastered", IF(P19>=0.8, "Strong", IF(P19>=0.7, "Developing", "Weak"))) | S19: =P19+ROW()/100000
F20: =IF(AND(ISNUMBER(D20), ISNUMBER(E20)), D20+E20, "") | M20: Expression of Ideas | P20: =IF(N20>0, O20/N20, 1.0) | Q20: =COUNTIFS('Error Log'!$F$2:$F$500, M20) | R20: =IF(P20>=0.9, "Mastered", IF(P20>=0.8, "Strong", IF(P20>=0.7, "Developing", "Weak"))) | S20: =P20+ROW()/100000
F21: =IF(AND(ISNUMBER(D21), ISNUMBER(E21)), D21+E21, "") | M21: Standard English Conventions | P21: =IF(N21>0, O21/N21, 1.0) | Q21: =COUNTIFS('Error Log'!$F$2:$F$500, M21) | R21: =IF(P21>=0.9, "Mastered", IF(P21>=0.8, "Strong", IF(P21>=0.7, "Developing", "Weak"))) | S21: =P21+ROW()/100000
F22: =IF(AND(ISNUMBER(D22), ISNUMBER(E22)), D22+E22, "")
F23: =IF(AND(ISNUMBER(D23), ISNUMBER(E23)), D23+E23, "")
F24: =IF(AND(ISNUMBER(D24), ISNUMBER(E24)), D24+E24, "")
F25: =IF(AND(ISNUMBER(D25), ISNUMBER(E25)), D25+E25, "")
F26: =IF(AND(ISNUMBER(D26), ISNUMBER(E26)), D26+E26, "")
F27: =IF(AND(ISNUMBER(D27), ISNUMBER(E27)), D27+E27, "")
F28: =IF(AND(ISNUMBER(D28), ISNUMBER(E28)), D28+E28, "")
F29: =IF(AND(ISNUMBER(D29), ISNUMBER(E29)), D29+E29, "")
F30: =IF(AND(ISNUMBER(D30), ISNUMBER(E30)), D30+E30, "")
F31: =IF(AND(ISNUMBER(D31), ISNUMBER(E31)), D31+E31, "")
F32: =IF(AND(ISNUMBER(D32), ISNUMBER(E32)), D32+E32, "")
F33: =IF(AND(ISNUMBER(D33), ISNUMBER(E33)), D33+E33, "")
... F35: =IF(AND(ISNUMBER(D35), ISNUMBER(E35)), D35+E35, "")
A37: PERSONALIZED STUDY ACTION PLAN
A38: Date Identified | B38: Weakness / Focus Topic | C38: Evidence (Test & Q#) | D38: Specific Action Required | E38: Target Deadline | F38: Status

Sheet Error Log
A1: Source / Site | B1: Section | C1: Correct Answer | D1: Your Answer | E1: Screenshot / Clip | F1: Topic | G1: Subtopic | H1: Question Type | I1: Error Type | J1: Root Cause | K1: Fix Strategy | L1: Time Taken (Sec) | M1: Retest Status | N1: Notes
O6: =IF(A6="", "", IFERROR(INDEX(Dashboard!$A$13:$A$35, MATCH(A6, Dashboard!$B$13:$B$35, 0)), ""))
O7: =IF(A7="", "", IFERROR(INDEX(Dashboard!$A$13:$A$35, MATCH(A7, Dashboard!$B$13:$B$35, 0)), ""))
O8: =IF(A8="", "", IFERROR(INDEX(Dashboard!$A$13:$A$35, MATCH(A8, Dashboard!$B$13:$B$35, 0)), ""))
O9: =IF(A9="", "", IFERROR(INDEX(Dashboard!$A$13:$A$35, MATCH(A9, Dashboard!$B$13:$B$35, 0)), ""))
O10: =IF(A10="", "", IFERROR(INDEX(Dashboard!$A$13:$A$35, MATCH(A10, Dashboard!$B$13:$B$35, 0)), ""))
O11: =IF(A11="", "", IFERROR(INDEX(Dashboard!$A$13:$A$35, MATCH(A11, Dashboard!$B$13:$B$35, 0)), ""))
O12: =IF(A12="", "", IFERROR(INDEX(Dashboard!$A$13:$A$35, MATCH(A12, Dashboard!$B$13:$B$35, 0)), ""))
O13: =IF(A13="", "", IFERROR(INDEX(Dashboard!$A$13:$A$35, MATCH(A13, Dashboard!$B$13:$B$35, 0)), ""))
O14: =IF(A14="", "", IFERROR(INDEX(Dashboard!$A$13:$A$35, MATCH(A14, Dashboard!$B$13:$B$35, 0)), ""))
O15: =IF(A15="", "", IFERROR(INDEX(Dashboard!$A$13:$A$35, MATCH(A15, Dashboard!$B$13:$B$35, 0)), ""))
O16: =IF(A16="", "", IFERROR(INDEX(Dashboard!$A$13:$A$35, MATCH(A16, Dashboard!$B$13:$B$35, 0)), ""))
O17: =IF(A17="", "", IFERROR(INDEX(Dashboard!$A$13:$A$35, MATCH(A17, Dashboard!$B$13:$B$35, 0)), ""))
... O500: =IF(A500="", "", IFERROR(INDEX(Dashboard!$A$13:$A$35, MATCH(A500, Dashboard!$B$13:$B$35, 0)), ""))

Sheet Config
A1: Section | B1: Difficulty | C1: Topic | D1: Error Type | E1: Root Cause | F1: Fix Strategy | G1: Retest Status | H1: Action Status | I1: Subtopic | J1: Error Type | K1: Count | L1: Helper | N1: Root Cause | O1: Count | P1: Helper | R1: Topic | S1: Count | T1: Helper | V1: Week Ending | W1: Knowledge Gap | X1: Misread Q | Y1: Process Error | Z1: Careless Error | AA1: Time Pressure | AB1: Total Errors | AD1: Month | AE1: Total Errors | AF1: Math Errors | AG1: Reading Errors | AH1: Question Type
A2: Math | B2: Easy | C2: Algebra | D2: Knowledge Gap (Concept Untrained) | E2: Concept was never learned or studied | F2: Study/Review the core mathematical concept from scratch | G2: Not Reviewed | H2: Not Started | I2: Linear Equations (1 Variable) | J2: Knowledge Gap (Concept Untrained) | K2: =COUNTIFS('Error Log'!$I$2:$I$500, J2) | L2: =K2-ROW()/100000 | N2: Concept was never learned or studied | O2: =COUNTIFS('Error Log'!$J$2:$J$500, N2) | P2: =O2-ROW()/100000 | R2: Algebra | S2: =COUNTIFS('Error Log'!$F$2:$F$500, R2) | T2: =S2-ROW()/100000 | V2: 46149 | W2: =COUNTIFS('Error Log'!$O$2:$O$500, ">="&(V2-6), 'Error Log'!$O$2:$O$500, "<="&V2, 'Error Log'!$I$2:$I$500, "Knowledge Gap*") | X2: =COUNTIFS('Error Log'!$O$2:$O$500, ">="&(V2-6), 'Error Log'!$O$2:$O$500, "<="&V2, 'Error Log'!$I$2:$I$500, "Misread*") | Y2: =COUNTIFS('Error Log'!$O$2:$O$500, ">="&(V2-6), 'Error Log'!$O$2:$O$500, "<="&V2, 'Error Log'!$I$2:$I$500, "Process*") | Z2: =COUNTIFS('Error Log'!$O$2:$O$500, ">="&(V2-6), 'Error Log'!$O$2:$O$500, "<="&V2, 'Error Log'!$I$2:$I$500, "Careless*") | AA2: =COUNTIFS('Error Log'!$O$2:$O$500, ">="&(V2-6), 'Error Log'!$O$2:$O$500, "<="&V2, 'Error Log'!$I$2:$I$500, "Time*") | AB2: =SUM(W2:AA2) | AD2: May 2026 | AE2: =COUNTIFS('Error Log'!$O$2:$O$500, ">="&DATE(2026,5,1), 'Error Log'!$O$2:$O$500, "<="&DATE(2026,5,31)) | AF2: =COUNTIFS('Error Log'!$O$2:$O$500, ">="&DATE(2026,5,1), 'Error Log'!$O$2:$O$500, "<="&DATE(2026,5,31), 'Error Log'!$B$2:$B$500, "Math") | AG2: =COUNTIFS('Error Log'!$O$2:$O$500, ">="&DATE(2026,5,1), 'Error Log'!$O$2:$O$500, "<="&DATE(2026,5,31), 'Error Log'!$B$2:$B$500, "Reading & Writing") | AH2: Math MCQ (Algebra)
A3: Reading & Writing | B3: Medium | C3: Advanced Math | D3: Knowledge Gap (Forgotten Details) | E3: Concept was studied but not practiced enough | F3: Memorize formula/rule (create physical or digital flashcard) | G3: Flagged for Retest | H3: In Progress | I3: Linear Equations (2 Variables) | J3: Knowledge Gap (Forgotten Details) | K3: =COUNTIFS('Error Log'!$I$2:$I$500, J3) | L3: =K3-ROW()/100000 | N3: Concept was studied but not practiced enough | O3: =COUNTIFS('Error Log'!$J$2:$J$500, N3) | P3: =O3-ROW()/100000 | R3: Advanced Math | S3: =COUNTIFS('Error Log'!$F$2:$F$500, R3) | T3: =S3-ROW()/100000 | V3: 46156 | W3: =COUNTIFS('Error Log'!$O$2:$O$500, ">="&(V3-6), 'Error Log'!$O$2:$O$500, "<="&V3, 'Error Log'!$I$2:$I$500, "Knowledge Gap*") | X3: =COUNTIFS('Error Log'!$O$2:$O$500, ">="&(V3-6), 'Error Log'!$O$2:$O$500, "<="&V3, 'Error Log'!$I$2:$I$500, "Misread*") | Y3: =COUNTIFS('Error Log'!$O$2:$O$500, ">="&(V3-6), 'Error Log'!$O$2:$O$500, "<="&V3, 'Error Log'!$I$2:$I$500, "Process*") | Z3: =COUNTIFS('Error Log'!$O$2:$O$500, ">="&(V3-6), 'Error Log'!$O$2:$O$500, "<="&V3, 'Error Log'!$I$2:$I$500, "Careless*") | AA3: =COUNTIFS('Error Log'!$O$2:$O$500, ">="&(V3-6), 'Error Log'!$O$2:$O$500, "<="&V3, 'Error Log'!$I$2:$I$500, "Time*") | AB3: =SUM(W3:AA3) | AD3: June 2026 | AE3: =COUNTIFS('Error Log'!$O$2:$O$500, ">="&DATE(2026,6,1), 'Error Log'!$O$2:$O$500, "<="&DATE(2026,6,30)) | AF3: =COUNTIFS('Error Log'!$O$2:$O$500, ">="&DATE(2026,6,1), 'Error Log'!$O$2:$O$500, "<="&DATE(2026,6,30), 'Error Log'!$B$2:$B$500, "Math") | AG3: =COUNTIFS('Error Log'!$O$2:$O$500, ">="&DATE(2026,6,1), 'Error Log'!$O$2:$O$500, "<="&DATE(2026,6,30), 'Error Log'!$B$2:$B$500, "Reading & Writing") | AH3: Math SPR (Algebra)
B4: Hard | C4: Problem Solving & Data Analysis | D4: Formula Misrecall / Incorrect Usage | E4: Forgot specific math formula or identity | F4: Review standard English grammar and punctuation rules | G4: Retest Failed | H4: Completed | I4: Linear Functions & Graphs | J4: Formula Misrecall / Incorrect Usage | K4: =COUNTIFS('Error Log'!$I$2:$I$500, J4) | L4: =K4-ROW()/100000 | N4: Forgot specific math formula or identity | O4: =COUNTIFS('Error Log'!$J$2:$J$500, N4) | P4: =O4-ROW()/100000 | R4: Problem Solving & Data Analysis | S4: =COUNTIFS('Error Log'!$F$2:$F$500, R4) | T4: =S4-ROW()/100000 | V4: 46163 | W4: =COUNTIFS('Error Log'!$O$2:$O$500, ">="&(V4-6), 'Error Log'!$O$2:$O$500, "<="&V4, 'Error Log'!$I$2:$I$500, "Knowledge Gap*") | X4: =COUNTIFS('Error Log'!$O$2:$O$500, ">="&(V4-6), 'Error Log'!$O$2:$O$500, "<="&V4, 'Error Log'!$I$2:$I$500, "Misread*") | Y4: =COUNTIFS('Error Log'!$O$2:$O$500, ">="&(V4-6), 'Error Log'!$O$2:$O$500, "<="&V4, 'Error Log'!$I$2:$I$500, "Process*") | Z4: =COUNTIFS('Error Log'!$O$2:$O$500, ">="&(V4-6), 'Error Log'!$O$2:$O$500, "<="&V4, 'Error Log'!$I$2:$I$500, "Careless*") | AA4: =COUNTIFS('Error Log'!$O$2:$O$500, ">="&(V4-6), 'Error Log'!$O$2:$O$500, "<="&V4, 'Error Log'!$I$2:$I$500, "Time*") | AB4: =SUM(W4:AA4) | AH4: Math MCQ (Advanced Math)
C5: Geometry & Trigonometry | D5: Grammar Rule Misrecall / Confusion | E5: Forgot specific grammar/punctuation rule | F5: Add word and definition to personal SAT vocabulary log | G5: Retest Passed (Mastered) | I5: Systems of Linear Equations (No/Infinite Solutions) | J5: Grammar Rule Misrecall / Confusion | K5: =COUNTIFS('Error Log'!$I$2:$I$500, J5) | L5: =K5-ROW()/100000 | N5: Forgot specific grammar/punctuation rule | O5: =COUNTIFS('Error Log'!$J$2:$J$500, N5) | P5: =O5-ROW()/100000 | R5: Geometry & Trigonometry | S5: =COUNTIFS('Error Log'!$F$2:$F$500, R5) | T5: =S5-ROW()/100000 | V5: 46170 | W5: =COUNTIFS('Error Log'!$O$2:$O$500, ">="&(V5-6), 'Error Log'!$O$2:$O$500, "<="&V5, 'Error Log'!$I$2:$I$500, "Knowledge Gap*") | X5: =COUNTIFS('Error Log'!$O$2:$O$500, ">="&(V5-6), 'Error Log'!$O$2:$O$500, "<="&V5, 'Error Log'!$I$2:$I$500, "Misread*") | Y5: =COUNTIFS('Error Log'!$O$2:$O$500, ">="&(V5-6), 'Error Log'!$O$2:$O$500, "<="&V5, 'Error Log'!$I$2:$I$500, "Process*") | Z5: =COUNTIFS('Error Log'!$O$2:$O$500, ">="&(V5-6), 'Error Log'!$O$2:$O$500, "<="&V5, 'Error Log'!$I$2:$I$500, "Careless*") | AA5: =COUNTIFS('Error Log'!$O$2:$O$500, ">="&(V5-6), 'Error Log'!$O$2:$O$500, "<="&V5, 'Error Log'!$I$2:$I$500, "Time*") | AB5: =SUM(W5:AA5) | AH5: Math SPR (Advanced Math)
C6: Information & Ideas | D6: Desmos Over-Reliance (Inefficient Method) | E6: Misread keyword in question (e.g., 'not', 'except', 'must') | F6: Complete 20+ practice questions on this specific subtopic | I6: Systems of Linear Equations (Solving) | J6: Desmos Over-Reliance (Inefficient Method) | K6: =COUNTIFS('Error Log'!$I$2:$I$500, J6) | L6: =K6-ROW()/100000 | N6: Misread keyword in question (e.g., 'not', 'except', 'must') | O6: =COUNTIFS('Error Log'!$J$2:$J$500, N6) | P6: =O6-ROW()/100000 | R6: Information & Ideas | S6: =COUNTIFS('Error Log'!$F$2:$F$500, R6) | T6: =S6-ROW()/100000 | V6: 46177 | W6: =COUNTIFS('Error Log'!$O$2:$O$500, ">="&(V6-6), 'Error Log'!$O$2:$O$500, "<="&V6, 'Error Log'!$I$2:$I$500, "Knowledge Gap*") | X6: =COUNTIFS('Error Log'!$O$2:$O$500, ">="&(V6-6), 'Error Log'!$O$2:$O$500, "<="&V6, 'Error Log'!$I$2:$I$500, "Misread*") | Y6: =COUNTIFS('Error Log'!$O$2:$O$500, ">="&(V6-6), 'Error Log'!$O$2:$O$500, "<="&V6, 'Error Log'!$I$2:$I$500, "Process*") | Z6: =COUNTIFS('Error Log'!$O$2:$O$500, ">="&(V6-6), 'Error Log'!$O$2:$O$500, "<="&V6, 'Error Log'!$I$2:$I$500, "Careless*") | AA6: =COUNTIFS('Error Log'!$O$2:$O$500, ">="&(V6-6), 'Error Log'!$O$2:$O$500, "<="&V6, 'Error Log'!$I$2:$I$500, "Time*") | AB6: =SUM(W6:AA6) | AH6: Math MCQ (Problem Solving & Data Analysis)
C7: Craft & Structure | D7: Desmos Input Error (Syntax / Typo) | E7: Ignored constraint (e.g., 'x > 0', 'integer', 'positive') | F7: Do a timed drill (10-15 questions) for this domain | I7: Linear Inequalities (1 Variable) | J7: Desmos Input Error (Syntax / Typo) | K7: =COUNTIFS('Error Log'!$I$2:$I$500, J7) | L7: =K7-ROW()/100000 | N7: Ignored constraint (e.g., 'x > 0', 'integer', 'positive') | O7: =COUNTIFS('Error Log'!$J$2:$J$500, N7) | P7: =O7-ROW()/100000 | R7: Craft & Structure | S7: =COUNTIFS('Error Log'!$F$2:$F$500, R7) | T7: =S7-ROW()/100000 | V7: 46184 | W7: =COUNTIFS('Error Log'!$O$2:$O$500, ">="&(V7-6), 'Error Log'!$O$2:$O$500, "<="&V7, 'Error Log'!$I$2:$I$500, "Knowledge Gap*") | X7: =COUNTIFS('Error Log'!$O$2:$O$500, ">="&(V7-6), 'Error Log'!$O$2:$O$500, "<="&V7, 'Error Log'!$I$2:$I$500, "Misread*") | Y7: =COUNTIFS('Error Log'!$O$2:$O$500, ">="&(V7-6), 'Error Log'!$O$2:$O$500, "<="&V7, 'Error Log'!$I$2:$I$500, "Process*") | Z7: =COUNTIFS('Error Log'!$O$2:$O$500, ">="&(V7-6), 'Error Log'!$O$2:$O$500, "<="&V7, 'Error Log'!$I$2:$I$500, "Careless*") | AA7: =COUNTIFS('Error Log'!$O$2:$O$500, ">="&(V7-6), 'Error Log'!$O$2:$O$500, "<="&V7, 'Error Log'!$I$2:$I$500, "Time*") | AB7: =SUM(W7:AA7) | AH7: Math SPR (Problem Solving & Data Analysis)
C8: Expression of Ideas | D8: Desmos Window / Scale Misinterpretation | E8: Solved for x but question asked for another expression (e.g., y, 2x, x+3) | F8: Do an untimed drill to focus on step-by-step accuracy | I8: Linear Inequalities (2 Variables & Systems) | J8: Desmos Window / Scale Misinterpretation | K8: =COUNTIFS('Error Log'!$I$2:$I$500, J8) | L8: =K8-ROW()/100000 | N8: Solved for x but question asked for another expression (e.g., y, 2x, x+3) | O8: =COUNTIFS('Error Log'!$J$2:$J$500, N8) | P8: =O8-ROW()/100000 | R8: Expression of Ideas | S8: =COUNTIFS('Error Log'!$F$2:$F$500, R8) | T8: =S8-ROW()/100000 | V8: 46191 | W8: =COUNTIFS('Error Log'!$O$2:$O$500, ">="&(V8-6), 'Error Log'!$O$2:$O$500, "<="&V8, 'Error Log'!$I$2:$I$500, "Knowledge Gap*") | X8: =COUNTIFS('Error Log'!$O$2:$O$500, ">="&(V8-6), 'Error Log'!$O$2:$O$500, "<="&V8, 'Error Log'!$I$2:$I$500, "Misread*") | Y8: =COUNTIFS('Error Log'!$O$2:$O$500, ">="&(V8-6), 'Error Log'!$O$2:$O$500, "<="&V8, 'Error Log'!$I$2:$I$500, "Process*") | Z8: =COUNTIFS('Error Log'!$O$2:$O$500, ">="&(V8-6), 'Error Log'!$O$2:$O$500, "<="&V8, 'Error Log'!$I$2:$I$500, "Careless*") | AA8: =COUNTIFS('Error Log'!$O$2:$O$500, ">="&(V8-6), 'Error Log'!$O$2:$O$500, "<="&V8, 'Error Log'!$I$2:$I$500, "Time*") | AB8: =SUM(W8:AA8) | AH8: Math MCQ (Geometry & Trigonometry)
C9: Standard English Conventions | D9: Desmos Mode Error (Radians vs. Degrees) | E9: Basic arithmetic slip (addition, subtraction, multiplication, division) | F9: Practice solving this algebraic problem type without Desmos | I9: Linear Equations (Word Problems) | J9: Desmos Mode Error (Radians vs. Degrees) | K9: =COUNTIFS('Error Log'!$I$2:$I$500, J9) | L9: =K9-ROW()/100000 | N9: Basic arithmetic slip (addition, subtraction, multiplication, division) | O9: =COUNTIFS('Error Log'!$J$2:$J$500, N9) | P9: =O9-ROW()/100000 | R9: Standard English Conventions | S9: =COUNTIFS('Error Log'!$F$2:$F$500, R9) | T9: =S9-ROW()/100000 | AH9: Math SPR (Geometry & Trigonometry)
D10: Careless Arithmetic (Simple Addition/Subtraction) | E10: Positive/negative sign flip during algebraic step | F10: Practice Desmos shortcuts (regression, graphing intersections, systems) | I10: Linear Functions (Slope & Intercept Interpretations) | J10: Careless Arithmetic (Simple Addition/Subtraction) | K10: =COUNTIFS('Error Log'!$I$2:$I$500, J10) | L10: =K10-ROW()/100000 | N10: Positive/negative sign flip during algebraic step | O10: =COUNTIFS('Error Log'!$J$2:$J$500, N10) | P10: =O10-ROW()/100000 | AH10: Reading MCQ (Central Ideas & Details)
D11: Careless Arithmetic (Sign Error +/-) | E11: Fraction or decimal calculation/conversion error | F11: Verify Desmos settings (Radian/Degree mode) before starting | I11: Systems of Linear Equations (Word Problems) | J11: Careless Arithmetic (Sign Error +/-) | K11: =COUNTIFS('Error Log'!$I$2:$I$500, J11) | L11: =K11-ROW()/100000 | N11: Fraction or decimal calculation/conversion error | O11: =COUNTIFS('Error Log'!$J$2:$J$500, N11) | P11: =O11-ROW()/100000 | AH11: Reading MCQ (Command of Evidence - Textual)
D12: Careless Arithmetic (Multiplication/Division) | E12: Exponent or radical simplification rule applied incorrectly | F12: Practice grid-zoom calibration in Desmos for graphs | I12: Graphing Linear Inequalities (Shaded Regions) | J12: Careless Arithmetic (Multiplication/Division) | K12: =COUNTIFS('Error Log'!$I$2:$I$500, J12) | L12: =K12-ROW()/100000 | N12: Exponent or radical simplification rule applied incorrectly | O12: =COUNTIFS('Error Log'!$J$2:$J$500, N12) | P12: =O12-ROW()/100000 | AH12: Reading MCQ (Command of Evidence - Quantitative)
D13: Algebraic Manipulation Slip (Distribution/Signs) | E13: Incorrect factoring or distribution of algebraic terms | F13: Practice writing clear, organized scratchpad steps | I13: Absolute Value Equations (Linear) | J13: Algebraic Manipulation Slip (Distribution/Signs) | K13: =COUNTIFS('Error Log'!$I$2:$I$500, J13) | L13: =K13-ROW()/100000 | N13: Incorrect factoring or distribution of algebraic terms | O13: =COUNTIFS('Error Log'!$J$2:$J$500, N13) | P13: =O13-ROW()/100000 | AH13: Reading MCQ (Inferences)
D14: Exponent / Power Rule Error | E14: Desmos typo: entered numbers or variables incorrectly | F14: Implement 'Read the Question Twice' rule for word problems | I14: Absolute Value Inequalities (Linear) | J14: Exponent / Power Rule Error | K14: =COUNTIFS('Error Log'!$I$2:$I$500, J14) | L14: =K14-ROW()/100000 | N14: Desmos typo: entered numbers or variables incorrectly | O14: =COUNTIFS('Error Log'!$J$2:$J$500, N14) | P14: =O14-ROW()/100000 | AH14: Reading MCQ (Words in Context)
D15: Misread Question Constraint (e.g. integer vs constant) | E15: Desmos setting: calculator was in wrong angle mode (Radian/Degree) | F15: Underline/circle the final variable or expression being asked for | I15: Quadratic Equations (Solving by Factoring/Formula) | J15: Misread Question Constraint (e.g. integer vs constant) | K15: =COUNTIFS('Error Log'!$I$2:$I$500, J15) | L15: =K15-ROW()/100000 | N15: Desmos setting: calculator was in wrong angle mode (Radian/Degree) | O15: =COUNTIFS('Error Log'!$J$2:$J$500, N15) | P15: =O15-ROW()/100000 | AH15: Reading MCQ (Text Structure & Purpose)
D16: Solved for Wrong Variable (e.g. x instead of 2x) | E16: Desmos window: did not zoom out far enough to see intersections | F16: Write down all constraints explicitly before solving | I16: Quadratic Functions & Parabolas (Vertex & Axis) | J16: Solved for Wrong Variable (e.g. x instead of 2x) | K16: =COUNTIFS('Error Log'!$I$2:$I$500, J16) | L16: =K16-ROW()/100000 | N16: Desmos window: did not zoom out far enough to see intersections | O16: =COUNTIFS('Error Log'!$J$2:$J$500, N16) | P16: =O16-ROW()/100000 | AH16: Reading MCQ (Cross-Text Connections)
D17: Misread Units (e.g. hours vs. minutes) | E17: Desmos reading: clicked wrong point or misread coordinate value | F17: Practice the Process of Elimination: write down why wrong choices are wrong | I17: Exponential Growth & Decay (Word Problems) | J17: Misread Units (e.g. hours vs. minutes) | K17: =COUNTIFS('Error Log'!$I$2:$I$500, J17) | L17: =K17-ROW()/100000 | N17: Desmos reading: clicked wrong point or misread coordinate value | O17: =COUNTIFS('Error Log'!$J$2:$J$500, N17) | P17: =O17-ROW()/100000 | AH17: Writing MCQ (Transitions)
D18: Misread Scale / Axis Labels | E18: Did not write down intermediate steps (tried to do it all mentally) | F18: Read passages with focus on main idea/tone, ignoring minor details | I18: Exponential Graphs & Percent Rates | J18: Misread Scale / Axis Labels | K18: =COUNTIFS('Error Log'!$I$2:$I$500, J18) | L18: =K18-ROW()/100000 | N18: Did not write down intermediate steps (tried to do it all mentally) | O18: =COUNTIFS('Error Log'!$J$2:$J$500, N18) | P18: =O18-ROW()/100000 | AH18: Writing MCQ (Rhetorical Synthesis)
D19: Trap Answer distractor choice | E19: Scratchpad work was too messy to follow, causing copy error | F19: Annotate the passage briefly to track arguments | I19: Polynomials & Factoring (Remainder Theorem) | J19: Trap Answer distractor choice | K19: =COUNTIFS('Error Log'!$I$2:$I$500, J19) | L19: =K19-ROW()/100000 | N19: Scratchpad work was too messy to follow, causing copy error | O19: =COUNTIFS('Error Log'!$J$2:$J$500, N19) | P19: =O19-ROW()/100000 | AH19: Writing MCQ (Standard English Conventions)
D20: Second-Guessing (Changed correct to incorrect) | E20: Fell for a common SAT distractor answer trap | F20: Read all four answer choices fully before selecting one | I20: Radical & Rational Equations | J20: Second-Guessing (Changed correct to incorrect) | K20: =COUNTIFS('Error Log'!$I$2:$I$500, J20) | L20: =K20-ROW()/100000 | N20: Fell for a common SAT distractor answer trap | O20: =COUNTIFS('Error Log'!$J$2:$J$500, N20) | P20: =O20-ROW()/100000
D21: Overthinking (Read too deep into passage) | E21: Eliminated the correct answer choice too early | F21: Set a strict 90-second limit per question (flag and skip if exceeded) | I21: Systems of Non-Linear Equations | J21: Overthinking (Read too deep into passage) | K21: =COUNTIFS('Error Log'!$I$2:$I$500, J21) | L21: =K21-ROW()/100000 | N21: Eliminated the correct answer choice too early | O21: =COUNTIFS('Error Log'!$J$2:$J$500, N21) | P21: =O21-ROW()/100000
D22: Underthinking (Skimmed too quickly / Rushed) | E22: Overthought the passage (imported external assumptions) | F22: Retake this exact question in 7 days (spaced repetition) | I22: Function Notation & Transformations | J22: Underthinking (Skimmed too quickly / Rushed) | K22: =COUNTIFS('Error Log'!$I$2:$I$500, J22) | L22: =K22-ROW()/100000 | N22: Overthought the passage (imported external assumptions) | O22: =COUNTIFS('Error Log'!$J$2:$J$500, N22) | P22: =O22-ROW()/100000
D23: Pacing: spent too long on one question | E23: Under-read the passage (missed transition word or tone shift) | F23: Retake this exact question in 14 days | I23: Quadratic Equations (Discriminant & Number of Solutions) | J23: Pacing: spent too long on one question | K23: =COUNTIFS('Error Log'!$I$2:$I$500, J23) | L23: =K23-ROW()/100000 | N23: Under-read the passage (missed transition word or tone shift) | O23: =COUNTIFS('Error Log'!$J$2:$J$500, N23) | P23: =O23-ROW()/100000
D24: Time Pressure: rushed choice at the end | E24: Confused the perspective of Author 1 vs Author 2 | F24: Explain the solution out loud to verify understanding (Feynman Technique) | I24: Quadratic Functions (Vertex Form vs Standard Form vs Factored Form) | J24: Time Pressure: rushed choice at the end | K24: =COUNTIFS('Error Log'!$I$2:$I$500, J24) | L24: =K24-ROW()/100000 | N24: Confused the perspective of Author 1 vs Author 2 | O24: =COUNTIFS('Error Log'!$J$2:$J$500, N24) | P24: =O24-ROW()/100000
D25: Educated Guess (Eliminated 2 options) | E25: Misread numerical values or labels in data table/graph | F25: Backsolve by plugging in answer choices | I25: Exponents & Radicals (Rules of Exponents) | J25: Educated Guess (Eliminated 2 options) | K25: =COUNTIFS('Error Log'!$I$2:$I$500, J25) | L25: =K25-ROW()/100000 | N25: Misread numerical values or labels in data table/graph | O25: =COUNTIFS('Error Log'!$J$2:$J$500, N25) | P25: =O25-ROW()/100000
D26: Blind Guessing | E26: Misidentified the specific goal of the rhetorical synthesis bullets | F26: Test algebraic equivalence by plugging in simple numbers (0, 1, -1) | I26: Dividing Polynomials (Synthetic/Long Division) | J26: Blind Guessing | K26: =COUNTIFS('Error Log'!$I$2:$I$500, J26) | L26: =K26-ROW()/100000 | N26: Misidentified the specific goal of the rhetorical synthesis bullets | O26: =COUNTIFS('Error Log'!$J$2:$J$500, N26) | P26: =O26-ROW()/100000
D27: Reading: Text Evidence Misinterpretation | E27: Confused logical transitions (e.g., 'however' vs 'furthermore') | F27: Double-check units and scale conversions (e.g. minutes to hours) | I27: Rational Functions & Asymptotes | J27: Reading: Text Evidence Misinterpretation | K27: =COUNTIFS('Error Log'!$I$2:$I$500, J27) | L27: =K27-ROW()/100000 | N27: Confused logical transitions (e.g., 'however' vs 'furthermore') | O27: =COUNTIFS('Error Log'!$J$2:$J$500, N27) | P27: =O27-ROW()/100000
D28: Reading: Data Table / Graph Misread | E28: Misidentified subject or verb in complex sentence structure | F28: Review common trap answer patterns in prep book / online resources | I28: Composite Functions (f(g(x))) | J28: Reading: Data Table / Graph Misread | K28: =COUNTIFS('Error Log'!$I$2:$I$500, J28) | L28: =K28-ROW()/100000 | N28: Misidentified subject or verb in complex sentence structure | O28: =COUNTIFS('Error Log'!$J$2:$J$500, N28) | P28: =O28-ROW()/100000
D29: Reading: Vocabulary definition misunderstanding | E29: Ambiguous pronoun reference or incorrect pronoun case | F29: Take a 30-second breathing break between modules to reset focus | I29: Absolute Value Functions (Non-Linear) | J29: Reading: Vocabulary definition misunderstanding | K29: =COUNTIFS('Error Log'!$I$2:$I$500, J29) | L29: =K29-ROW()/100000 | N29: Ambiguous pronoun reference or incorrect pronoun case | O29: =COUNTIFS('Error Log'!$J$2:$J$500, N29) | P29: =O29-ROW()/100000
D30: Reading: Main idea vs Supporting detail confusion | E30: Misplaced apostrophe for singular vs plural possessives | F30: Do a full-length practice section to build mental endurance | I30: Graphing Nonlinear Functions (Intercepts & End Behavior) | J30: Reading: Main idea vs Supporting detail confusion | K30: =COUNTIFS('Error Log'!$I$2:$I$500, J30) | L30: =K30-ROW()/100000 | N30: Misplaced apostrophe for singular vs plural possessives | O30: =COUNTIFS('Error Log'!$J$2:$J$500, N30) | P30: =O30-ROW()/100000
D31: Reading: Cross-text perspective misattribution | E31: Dangling modifier describing the wrong noun | F31: Compare my solution step-by-step with the official explanation | I31: Ratios, Rates, & Proportions | J31: Reading: Cross-text perspective misattribution | K31: =COUNTIFS('Error Log'!$I$2:$I$500, J31) | L31: =K31-ROW()/100000 | N31: Dangling modifier describing the wrong noun | O31: =COUNTIFS('Error Log'!$J$2:$J$500, N31) | P31: =O31-ROW()/100000
... D33: Reading: Transition logic choice error | E33: Semicolon/colon punctuation rule misapplied | F33: Verify that my selected choice matches all constraints in the question | I33: Percents & Percent Change | J33: Reading: Transition logic choice error | K33: =COUNTIFS('Error Log'!$I$2:$I$500, J33) | L33: =K33-ROW()/100000 | N33: Semicolon/colon punctuation rule misapplied | O33: =COUNTIFS('Error Log'!$J$2:$J$500, N33) | P33: =O33-ROW()/100000
D34: Reading: Rhetorical synthesis goal mismatch | E34: Spent too much time on a difficult question (Sunk Cost Fallacy) | I34: Mean, Median, Mode & Range | J34: Reading: Rhetorical synthesis goal mismatch | K34: =COUNTIFS('Error Log'!$I$2:$I$500, J34) | L34: =K34-ROW()/100000 | N34: Spent too much time on a difficult question (Sunk Cost Fallacy) | O34: =COUNTIFS('Error Log'!$J$2:$J$500, N34) | P34: =O34-ROW()/100000
D35: Writing: Sentence structure error (Run-on/Fragment) | E35: Panicked due to time pressure in the second module | I35: Standard Deviation & Spread | J35: Writing: Sentence structure error (Run-on/Fragment) | K35: =COUNTIFS('Error Log'!$I$2:$I$500, J35) | L35: =K35-ROW()/100000 | N35: Panicked due to time pressure in the second module | O35: =COUNTIFS('Error Log'!$J$2:$J$500, N35) | P35: =O35-ROW()/100000
D36: Writing: Punctuation misinterpretation | E36: Rushed through easy questions and made silly slips | I36: Probability & Conditional Probability | J36: Writing: Punctuation misinterpretation | K36: =COUNTIFS('Error Log'!$I$2:$I$500, J36) | L36: =K36-ROW()/100000 | N36: Rushed through easy questions and made silly slips | O36: =COUNTIFS('Error Log'!$J$2:$J$500, N36) | P36: =O36-ROW()/100000
D37: Scratchpad / Copy-paste transcription error | E37: Second-guessed original correct choice and changed it | I37: Scatterplots & Line of Best Fit | J37: Scratchpad / Copy-paste transcription error | K37: =COUNTIFS('Error Log'!$I$2:$I$500, J37) | L37: =K37-ROW()/100000 | N37: Second-guessed original correct choice and changed it | O37: =COUNTIFS('Error Log'!$J$2:$J$500, N37) | P37: =O37-ROW()/100000
D38: Fatigue / Lack of Concentration | E38: Mental fatigue or brain fog near the end of a module | I38: Linear vs. Exponential Models | J38: Fatigue / Lack of Concentration | K38: =COUNTIFS('Error Log'!$I$2:$I$500, J38) | L38: =K38-ROW()/100000 | N38: Mental fatigue or brain fog near the end of a module | O38: =COUNTIFS('Error Log'!$J$2:$J$500, N38) | P38: =O38-ROW()/100000
D39: Process Error / Methodology Slip | E39: Unfamiliar vocabulary word in the context passage | I39: Margin of Error & Confidence Intervals | J39: Process Error / Methodology Slip | K39: =COUNTIFS('Error Log'!$I$2:$I$500, J39) | L39: =K39-ROW()/100000 | N39: Unfamiliar vocabulary word in the context passage | O39: =COUNTIFS('Error Log'!$J$2:$J$500, N39) | P39: =O39-ROW()/100000
E40: Assumed incorrect definition for a vocabulary word | I40: Observational Studies & Experiments | N40: Assumed incorrect definition for a vocabulary word | O40: =COUNTIFS('Error Log'!$J$2:$J$500, N40) | P40: =O40-ROW()/100000
E41: Did not plug in answers or test numbers to double check | I41: Density & Complex Ratios | N41: Did not plug in answers or test numbers to double check | O41: =COUNTIFS('Error Log'!$J$2:$J$500, N41) | P41: =O41-ROW()/100000
...
